Workbook
Name Slicer_Discount_Category: #N/A
Name Slicer_Product_Category: #N/A
Name Slicer_Rating_Category: #N/A

Sheet Clean Dataset
A1: Products | B1: Product Category | C1: Current Price | D1: Old Price | E1: Absolute Discount | F1: Discount | G1: Discount Category | H1: Reviews | I1: Rating | J1: Rating Category
A2: 6 In 1 Bottle Can Opener Multifunctional Easy Opener | B2: Kitchen & Dining | C2: 199 | D2: 553 | E2: =D2-C2 -> 354 | F2: 0.64 | G2: =IF(TableJumiaProducts[[#This Row],[Discount]]<20%, "Low Discount", IF(TableJumiaProducts[[#This Row],[Discount]]<=40%, "Medium Discount", "High Discount")) -> High Discount | J2: =IF(TableJumiaProducts[[#This Row],[Rating]]="","Uknown", IF(TableJumiaProducts[[#This Row],[Rating]]<3, "Poor", IF(TableJumiaProducts[[#This Row],[Rating]]<4.5, "Average", "Excellent"))) -> Uknown
A3: Creative Owl Shape Keychain Black | B3: Home & Office | C3: 199 | D3: 504 | E3: =D3-C3 -> 305 | F3: 0.61 | G3: =IF(TableJumiaProducts[[#This Row],[Discount]]<20%, "Low Discount", IF(TableJumiaProducts[[#This Row],[Discount]]<=40%, "Medium Discount", "High Discount")) -> High Discount | J3: =IF(TableJumiaProducts[[#This Row],[Rating]]="","Uknown", IF(TableJumiaProducts[[#This Row],[Rating]]<3, "Poor", IF(TableJumiaProducts[[#This Row],[Rating]]<4.5, "Average", "Excellent"))) -> Uknown | L3: Missing values | M3: Table | N3: =COUNTBLANK('Clean Dataset'!$A$2:$I$113) -> 110
A4: 5-PCS Stainless Steel Cooking Pot Set With Steamed Slices | B4: Kitchen & Dining | C4: 2115 | D4: 4700 | E4: =D4-C4 -> 2585 | F4: 0.55 | G4: =IF(TableJumiaProducts[[#This Row],[Discount]]<20%, "Low Discount", IF(TableJumiaProducts[[#This Row],[Discount]]<=40%, "Medium Discount", "High Discount")) -> High Discount | H4: 13 | I4: 2.1 | J4: =IF(TableJumiaProducts[[#This Row],[Rating]]="","Uknown", IF(TableJumiaProducts[[#This Row],[Rating]]<3, "Poor", IF(TableJumiaProducts[[#This Row],[Rating]]<4.5, "Average", "Excellent"))) -> Poor | M4: Product | N4: =COUNTBLANK('Clean Dataset'!$A$2:$A$113) -> 0
A5: LASA Folding Table Serving Stand | B5: Kitchen & Dining | C5: 1274 | D5: 2800 | E5: =D5-C5 -> 1526 | F5: 0.55 | G5: =IF(TableJumiaProducts[[#This Row],[Discount]]<20%, "Low Discount", IF(TableJumiaProducts[[#This Row],[Discount]]<=40%, "Medium Discount", "High Discount")) -> High Discount | H5: 5 | I5: 4.8 | J5: =IF(TableJumiaProducts[[#This Row],[Rating]]="","Uknown", IF(TableJumiaProducts[[#This Row],[Rating]]<3, "Poor", IF(TableJumiaProducts[[#This Row],[Rating]]<4.5, "Average", "Excellent"))) -> Excellent | M5: Current price | N5: =COUNTBLANK('Clean Dataset'!$C$2:$C$113) -> 0
A6: Simple Metal Dog Art Sculpture Decoration For Home Office | B6: Home & Office | C6: 399 | D6: 896 | E6: =D6-C6 -> 497 | F6: 0.55 | G6: =IF(TableJumiaProducts[[#This Row],[Discount]]<20%, "Low Discount", IF(TableJumiaProducts[[#This Row],[Discount]]<=40%, "Medium Discount", "High Discount")) -> High Discount | J6: =IF(TableJumiaProducts[[#This Row],[Rating]]="","Uknown", IF(TableJumiaProducts[[#This Row],[Rating]]<3, "Poor", IF(TableJumiaProducts[[#This Row],[Rating]]<4.5, "Average", "Excellent"))) -> Uknown | M6: Old price | N6: =COUNTBLANK('Clean Dataset'!$D$2:$D$113) -> 0
A7: LASA 3 Tier Bamboo Shoe Bench Storage Shelf | B7: Home & Office | C7: 2048 | D7: 4500 | E7: =D7-C7 -> 2452 | F7: 0.54 | G7: =IF(TableJumiaProducts[[#This Row],[Discount]]<20%, "Low Discount", IF(TableJumiaProducts[[#This Row],[Discount]]<=40%, "Medium Discount", "High Discount")) -> High Discount | H7: 7 | I7: 4.3 | J7: =IF(TableJumiaProducts[[#This Row],[Rating]]="","Uknown", IF(TableJumiaProducts[[#This Row],[Rating]]<3, "Poor", IF(TableJumiaProducts[[#This Row],[Rating]]<4.5, "Average", "Excellent"))) -> Average | M7: Discount | N7: =COUNTBLANK('Clean Dataset'!$F$2:$F$113) -> 0
A8: Mythco 120COB Solar Wall Ligt With Motion Sensor And Remote Control 3 Modes | B8: Garden & Outdoors | C8: 458 | D8: 986 | E8: =D8-C8 -> 528 | F8: 0.54 | G8: =IF(TableJumiaProducts[[#This Row],[Discount]]<20%, "Low Discount", IF(TableJumiaProducts[[#This Row],[Discount]]<=40%, "Medium Discount", "High Discount")) -> High Discount | H8: 10 | I8: 3 | J8: =IF(TableJumiaProducts[[#This Row],[Rating]]="","Uknown", IF(TableJumiaProducts[[#This Row],[Rating]]<3, "Poor", IF(TableJumiaProducts[[#This Row],[Rating]]<4.5, "Average", "Excellent"))) -> Average | M8: Review | N8: =COUNTBLANK(H2:H113) -> 55
A9: Classic Black Cat Cotton Hemp Pillow Case For Home Car | B9: Home & Office | C9: 171 | D9: 360 | E9: =D9-C9 -> 189 | F9: 0.53 | G9: =IF(TableJumiaProducts[[#This Row],[Discount]]<20%, "Low Discount", IF(TableJumiaProducts[[#This Row],[Discount]]<=40%, "Medium Discount", "High Discount")) -> High Discount | H9: 2 | I9: 5 | J9: =IF(TableJumiaProducts[[#This Row],[Rating]]="","Uknown", IF(TableJumiaProducts[[#This Row],[Rating]]<3, "Poor", IF(TableJumiaProducts[[#This Row],[Rating]]<4.5, "Average", "Excellent"))) -> Excellent | M9: Rating | N9: =COUNTBLANK(I2:I113) -> 55
A10: 3PCS Single Head Knitting Crochet Sweater Needle Set | B10: Clothing | C10: 38 | D10: 80 | E10: =D10-C10 -> 42 | F10: 0.53 | G10: =IF(TableJumiaProducts[[#This Row],[Discount]]<20%, "Low Discount", IF(TableJumiaProducts[[#This Row],[Discount]]<=40%, "Medium Discount", "High Discount")) -> High Discount | H10: 13 | I10: 3.3 | J10: =IF(TableJumiaProducts[[#This Row],[Rating]]="","Uknown", IF(TableJumiaProducts[[#This Row],[Rating]]<3, "Poor", IF(TableJumiaProducts[[#This Row],[Rating]]<4.5, "Average", "Excellent"))) -> Average | L10: Duplicates | M10: 3 rows removed
A11: Intelligent LED Body Sensor Wireless Lighting Night Light USB | B11: Appliances | C11: 325 | D11: 680 | E11: =D11-C11 -> 355 | F11: 0.52 | G11: =IF(TableJumiaProducts[[#This Row],[Discount]]<20%, "Low Discount", IF(TableJumiaProducts[[#This Row],[Discount]]<=40%, "Medium Discount", "High Discount")) -> High Discount | H11: 15 | I11: 2.7 | J11: =IF(TableJumiaProducts[[#This Row],[Rating]]="","Uknown", IF(TableJumiaProducts[[#This Row],[Rating]]<3, "Poor", IF(TableJumiaProducts[[#This Row],[Rating]]<4.5, "Average", "Excellent"))) -> Poor
A12: Exfoliate And Exfoliate Face Towel - Black | B12: Health & Beauty | C12: 185 | D12: 382 | E12: =D12-C12 -> 197 | F12: 0.52 | G12: =IF(TableJumiaProducts[[#This Row],[Discount]]<20%, "Low Discount", IF(TableJumiaProducts[[#This Row],[Discount]]<=40%, "Medium Discount", "High Discount")) -> High Discount | H12: 9 | I12: 4.3 | J12: =IF(TableJumiaProducts[[#This Row],[Rating]]="","Uknown", IF(TableJumiaProducts[[#This Row],[Rating]]<3, "Poor", IF(TableJumiaProducts[[#This Row],[Rating]]<4.5, "Average", "Excellent"))) -> Average | L12: Removing Ksh and comma in price columns
A13: Anti-Skid Absorbent Insulation Coaster For Home Office | B13: Home & Office | C13: 332 | D13: 684 | E13: =D13-C13 -> 352 | F13: 0.51 | G13: =IF(TableJumiaProducts[[#This Row],[Discount]]<20%, "Low Discount", IF(TableJumiaProducts[[#This Row],[Discount]]<=40%, "Medium Discount", "High Discount")) -> High Discount | H13: 2 | I13: 5 | J13: =IF(TableJumiaProducts[[#This Row],[Rating]]="","Uknown", IF(TableJumiaProducts[[#This Row],[Rating]]<3, "Poor", IF(TableJumiaProducts[[#This Row],[Rating]]<4.5, "Average", "Excellent"))) -> Excellent | M13: Used find and replace to remove ksh
A14: 2PCS Ice Silk Square Cushion Cover Pillowcases - 65x65cm | B14: Beddings & Sanitary | C14: 1200 | D14: 2400 | E14: =D14-C14 -> 1200 | F14: 0.5 | G14: =IF(TableJumiaProducts[[#This Row],[Discount]]<20%, "Low Discount", IF(TableJumiaProducts[[#This Row],[Discount]]<=40%, "Medium Discount", "High Discount")) -> High Discount | J14: =IF(TableJumiaProducts[[#This Row],[Rating]]="","Uknown", IF(TableJumiaProducts[[#This Row],[Rating]]<3, "Poor", IF(TableJumiaProducts[[#This Row],[Rating]]<4.5, "Average", "Excellent"))) -> Uknown | M14: Unchecked the comma separator from the mumbers
A15: 380ML USB Rechargeable Portable Small Blenders And Juicers | B15: Appliances | C15: 1000 | D15: 2000 | E15: =D15-C15 -> 1000 | F15: 0.5 | G15: =IF(TableJumiaProducts[[#This Row],[Discount]]<20%, "Low Discount", IF(TableJumiaProducts[[#This Row],[Discount]]<=40%, "Medium Discount", "High Discount")) -> High Discount | H15: 7 | I15: 2.3 | J15: =IF(TableJumiaProducts[[#This Row],[Rating]]="","Uknown", IF(TableJumiaProducts[[#This Row],[Rating]]<3, "Poor", IF(TableJumiaProducts[[#This Row],[Rating]]<4.5, "Average", "Excellent"))) -> Poor | M15: Can use the NUMBERVALUE() function
A16: Christmas Elk Fence Yard Lawn Decorations Cute For Holidays | B16: Garden & Outdoors | C16: 999 | D16: 2000 | E16: =D16-C16 -> 1001 | F16: 0.5 | G16: =IF(TableJumiaProducts[[#This Row],[Discount]]<20%, "Low Discount", IF(TableJumiaProducts[[#This Row],[Discount]]<=40%, "Medium Discount", "High Discount")) -> High Discount | J16: =IF(TableJumiaProducts[[#This Row],[Rating]]="","Uknown", IF(TableJumiaProducts[[#This Row],[Rating]]<3, "Poor", IF(TableJumiaProducts[[#This Row],[Rating]]<4.5, "Average", "Excellent"))) -> Uknown | L16: Standardizing the review column
A17: Wall Clock With Hidden Safe Box | B17: Home & Office | C17: 850 | D17: 1700 | E17: =D17-C17 -> 850 | F17: 0.5 | G17: =IF(TableJumiaProducts[[#This Row],[Discount]]<20%, "Low Discount", IF(TableJumiaProducts[[#This Row],[Discount]]<=40%, "Medium Discount", "High Discount")) -> High Discount | J17: =IF(TableJumiaProducts[[#This Row],[Rating]]="","Uknown", IF(TableJumiaProducts[[#This Row],[Rating]]<3, "Poor", IF(TableJumiaProducts[[#This Row],[Rating]]<4.5, "Average", "Excellent"))) -> Uknown | M17: Used the text to column feature under Data and set the delimitter as space then deleted the three columns to the right
A18: Wall-mounted Sticker Punch-free Plug Fixer | B18: Appliances | C18: 450 | D18: 900 | E18: =D18-C18 -> 450 | F18: 0.5 | G18: =IF(TableJumiaProducts[[#This Row],[Discount]]<20%, "Low Discount", IF(TableJumiaProducts[[#This Row],[Discount]]<=40%, "Medium Discount", "High Discount")) -> High Discount | H18: 1 | I18: 2 | J18: =IF(TableJumiaProducts[[#This Row],[Rating]]="","Uknown", IF(TableJumiaProducts[[#This Row],[Rating]]<3, "Poor", IF(TableJumiaProducts[[#This Row],[Rating]]<4.5, "Average", "Excellent"))) -> Poor
A19: Brush & Paintbrush Cleaning Tool Pink | B19: Appliances | C19: 299 | D19: 600 | E19: =D19-C19 -> 301 | F19: 0.5 | G19: =IF(TableJumiaProducts[[#This Row],[Discount]]<20%, "Low Discount", IF(TableJumiaProducts[[#This Row],[Discount]]<=40%, "Medium Discount", "High Discount")) -> High Discount | J19: =IF(TableJumiaProducts[[#This Row],[Rating]]="","Uknown", IF(TableJumiaProducts[[#This Row],[Rating]]<3, "Poor", IF(TableJumiaProducts[[#This Row],[Rating]]<4.5, "Average", "Excellent"))) -> Uknown | L19: Averages
A20: Modern Sofa Throw Pillow Cover-45x45cm-Blue&Red | B20: Home & Office | C20: 238 | D20: 476 | E20: =D20-C20 -> 238 | F20: 0.5 | G20: =IF(TableJumiaProducts[[#This Row],[Discount]]<20%, "Low Discount", IF(TableJumiaProducts[[#This Row],[Discount]]<=40%, "Medium Discount", "High Discount")) -> High Discount | J20: =IF(TableJumiaProducts[[#This Row],[Rating]]="","Uknown", IF(TableJumiaProducts[[#This Row],[Rating]]<3, "Poor", IF(TableJumiaProducts[[#This Row],[Rating]]<4.5, "Average", "Excellent"))) -> Uknown | L20: Current price | M20: =AVERAGE(C2:C113) -> 1186.8929
A21: LASA Aluminum Folding Truck Hand Cart - 68kg Max | B21: Home & Office | C21: 2025 | D21: 3971 | E21: =D21-C21 -> 1946 | F21: 0.49 | G21: =IF(TableJumiaProducts[[#This Row],[Discount]]<20%, "Low Discount", IF(TableJumiaProducts[[#This Row],[Discount]]<=40%, "Medium Discount", "High Discount")) -> High Discount | H21: 3 | I21: 5 | J21: =IF(TableJumiaProducts[[#This Row],[Rating]]="","Uknown", IF(TableJumiaProducts[[#This Row],[Rating]]<3, "Poor", IF(TableJumiaProducts[[#This Row],[Rating]]<4.5, "Average", "Excellent"))) -> Excellent | L21: Old price | M21: =AVERAGE(D2:D113) -> 1811.1071
A22: 3D Waterproof EVA Plastic Shower Curtain 1.8*2Mtrs | B22: Beddings & Sanitary | C22: 998 | D22: 1966 | E22: =D22-C22 -> 968 | F22: 0.49 | G22: =IF(TableJumiaProducts[[#This Row],[Discount]]<20%, "Low Discount", IF(TableJumiaProducts[[#This Row],[Discount]]<=40%, "Medium Discount", "High Discount")) -> High Discount | H22: 44 | I22: 4.6 | J22: =IF(TableJumiaProducts[[#This Row],[Rating]]="","Uknown", IF(TableJumiaProducts[[#This Row],[Rating]]<3, "Poor", IF(TableJumiaProducts[[#This Row],[Rating]]<4.5, "Average", "Excellent"))) -> Excellent | L22: Discount percentage | M22: =AVERAGE(TableJumiaProducts[Discount]) -> 0.36776786
A23: Bedroom Simple Floor Hanging Clothes Rack Single Pole Hat Rack - White | B23: Home & Office | C23: 979 | D23: 1920 | E23: =D23-C23 -> 941 | F23: 0.49 | G23: =IF(TableJumiaProducts[[#This Row],[Discount]]<20%, "Low Discount", IF(TableJumiaProducts[[#This Row],[Discount]]<=40%, "Medium Discount", "High Discount")) -> High Discount | H23: 1 | I23: 5 | J23: =IF(TableJumiaProducts[[#This Row],[Rating]]="","Uknown", IF(TableJumiaProducts[[#This Row],[Rating]]<3, "Poor", IF(TableJumiaProducts[[#This Row],[Rating]]<4.5, "Average", "Excellent"))) -> Excellent | L23: Rating | M23: =AVERAGE(TableJumiaProducts[Rating]) -> 3.8894737
A24: Angle Measuring Tool Full Metal Multi Angle Measuring Tool | B24: Appliances | C24: 799 | D24: 1567 | E24: =D24-C24 -> 768 | F24: 0.49 | G24: =IF(TableJumiaProducts[[#This Row],[Discount]]<20%, "Low Discount", IF(TableJumiaProducts[[#This Row],[Discount]]<=40%, "Medium Discount", "High Discount")) -> High Discount | J24: =IF(TableJumiaProducts[[#This Row],[Rating]]="","Uknown", IF(TableJumiaProducts[[#This Row],[Rating]]<3, "Poor", IF(TableJumiaProducts[[#This Row],[Rating]]<4.5, "Average", "Excellent"))) -> Uknown
A25: Car Phone Charging Stand | B25: Appliances | C25: 671 | D25: 1316 | E25: =D25-C25 -> 645 | F25: 0.49 | G25: =IF(TableJumiaProducts[[#This Row],[Discount]]<20%, "Low Discount", IF(TableJumiaProducts[[#This Row],[Discount]]<=40%, "Medium Discount", "High Discount")) -> High Discount | J25: =IF(TableJumiaProducts[[#This Row],[Rating]]="","Uknown", IF(TableJumiaProducts[[#This Row],[Rating]]<3, "Poor", IF(TableJumiaProducts[[#This Row],[Rating]]<4.5, "Average", "Excellent"))) -> Uknown
A26: Angle Measuring Tool Full Metal Multi Angle Measuring Tool | B26: Appliances | C26: 657 | D26: 1288 | E26: =D26-C26 -> 631 | F26: 0.49 | G26: =IF(TableJumiaProducts[[#This Row],[Discount]]<20%, "Low Discount", IF(TableJumiaProducts[[#This Row],[Discount]]<=40%, "Medium Discount", "High Discount")) -> High Discount | J26: =IF(TableJumiaProducts[[#This Row],[Rating]]="","Uknown", IF(TableJumiaProducts[[#This Row],[Rating]]<3, "Poor", IF(TableJumiaProducts[[#This Row],[Rating]]<4.5, "Average", "Excellent"))) -> Uknown | L26: Most and Least expensive products
A27: Baby Early Education Shape And Color Cognitive Training Toys | B27: Baby Products | C27: 525 | D27: 1029 | E27: =D27-C27 -> 504 | F27: 0.49 | G27: =IF(TableJumiaProducts[[#This Row],[Discount]]<20%, "Low Discount", IF(TableJumiaProducts[[#This Row],[Discount]]<=40%, "Medium Discount", "High Discount")) -> High Discount | J27: =IF(TableJumiaProducts[[#This Row],[Rating]]="","Uknown", IF(TableJumiaProducts[[#This Row],[Rating]]<3, "Poor", IF(TableJumiaProducts[[#This Row],[Rating]]<4.5, "Average", "Excellent"))) -> Uknown | L27: Most expensive | N27: =MAX(TableJumiaProducts[Current Price]) -> 3750 | O27: 32PCS Portable Cordless Drill Set With Cyclic Battery Drive -26 Variable Speed
A28: 4M Float Switch Water Level Controller -Water Tank | B28: Appliances | C28: 475 | D28: 931 | E28: =D28-C28 -> 456 | F28: 0.49 | G28: =IF(TableJumiaProducts[[#This Row],[Discount]]<20%, "Low Discount", IF(TableJumiaProducts[[#This Row],[Discount]]<=40%, "Medium Discount", "High Discount")) -> High Discount | J28: =IF(TableJumiaProducts[[#This Row],[Rating]]="","Uknown", IF(TableJumiaProducts[[#This Row],[Rating]]<3, "Poor", IF(TableJumiaProducts[[#This Row],[Rating]]<4.5, "Average", "Excellent"))) -> Uknown | L28: Least expensive | N28: =MIN(TableJumiaProducts[Current Price]) -> 38 | O28: 3PCS Single Head Knitting Crochet Sweater Needle Set
A29: 120W Cordless Vacuum Cleaners Handheld Electric Vacuum Cleaner | B29: Appliances | C29: 445 | D29: 873 | E29: =D29-C29 -> 428 | F29: 0.49 | G29: =IF(TableJumiaProducts[[#This Row],[Discount]]<20%, "Low Discount", IF(TableJumiaProducts[[#This Row],[Discount]]<=40%, "Medium Discount", "High Discount")) -> High Discount | H29: 69 | I29: 2.8 | J29: =IF(TableJumiaProducts[[#This Row],[Rating]]="","Uknown", IF(TableJumiaProducts[[#This Row],[Rating]]<3, "Poor", IF(TableJumiaProducts[[#This Row],[Rating]]<4.5, "Average", "Excellent"))) -> Poor
A30: Household Pineapple Peeler Peeler | B30: Kitchen & Dining | C30: 330 | D30: 647 | E30: =D30-C30 -> 317 | F30: 0.49 | G30: =IF(TableJumiaProducts[[#This Row],[Discount]]<20%, "Low Discount", IF(TableJumiaProducts[[#This Row],[Discount]]<=40%, "Medium Discount", "High Discount")) -> High Discount | H30: 1 | I30: 4 | J30: =IF(TableJumiaProducts[[#This Row],[Rating]]="","Uknown", IF(TableJumiaProducts[[#This Row],[Rating]]<3, "Poor", IF(TableJumiaProducts[[#This Row],[Rating]]<4.5, "Average", "Excellent"))) -> Average | L30: Correlation between Discount Percentage and Reviews | N30: =CORREL(TableJumiaProducts[Discount], TableJumiaProducts[Reviews]) -> -0.13682272
A31: Cartoon Car Decoration Cute Individuality For Car Home Desk | B31: Home & Office | C31: 274 | D31: 537 | E31: =D31-C31 -> 263 | F31: 0.49 | G31: =IF(TableJumiaProducts[[#This Row],[Discount]]<20%, "Low Discount", IF(TableJumiaProducts[[#This Row],[Discount]]<=40%, "Medium Discount", "High Discount")) -> High Discount | J31: =IF(TableJumiaProducts[[#This Row],[Rating]]="","Uknown", IF(TableJumiaProducts[[#This Row],[Rating]]<3, "Poor", IF(TableJumiaProducts[[#This Row],[Rating]]<4.5, "Average", "Excellent"))) -> Uknown
A32: 4 Piece Coloured Stainless Steel Kitchenware Set | B32: Kitchen & Dining | C32: 248 | D32: 486 | E32: =D32-C32 -> 238 | F32: 0.49 | G32: =IF(TableJumiaProducts[[#This Row],[Discount]]<20%, "Low Discount", IF(TableJumiaProducts[[#This Row],[Discount]]<=40%, "Medium Discount", "High Discount")) -> High Discount | J32: =IF(TableJumiaProducts[[#This Row],[Rating]]="","Uknown", IF(TableJumiaProducts[[#This Row],[Rating]]<3, "Poor", IF(TableJumiaProducts[[#This Row],[Rating]]<4.5, "Average", "Excellent"))) -> Uknown
A33: 7PCS Silicone Thumb Knife Finger Protector Vegetable Harvesting Knife | B33: Kitchen & Dining | C33: 230 | D33: 450 | E33: =D33-C33 -> 220 | F33: 0.49 | G33: =IF(TableJumiaProducts[[#This Row],[Discount]]<20%, "Low Discount", IF(TableJumiaProducts[[#This Row],[Discount]]<=40%, "Medium Discount", "High Discount")) -> High Discount | J33: =IF(TableJumiaProducts[[#This Row],[Rating]]="","Uknown", IF(TableJumiaProducts[[#This Row],[Rating]]<3, "Poor", IF(TableJumiaProducts[[#This Row],[Rating]]<4.5, "Average", "Excellent"))) -> Uknown
A34: Creative Owl Shape Keychain Black | B34: Home & Office | C34: 176 | D34: 345 | E34: =D34-C34 -> 169 | F34: 0.49 | G34: =IF(TableJumiaProducts[[#This Row],[Discount]]<20%, "Low Discount", IF(TableJumiaProducts[[#This Row],[Discount]]<=40%, "Medium Discount", "High Discount")) -> High Discount | J34: =IF(TableJumiaProducts[[#This Row],[Rating]]="","Uknown", IF(TableJumiaProducts[[#This Row],[Rating]]<3, "Poor", IF(TableJumiaProducts[[#This Row],[Rating]]<4.5, "Average", "Excellent"))) -> Uknown
A35: LED Eye Protection Desk Lamp , Study, Reading, USB Fan - Double Pen Holder | B35: Home & Office | C35: 1820 | D35: 3490 | E35: =D35-C35 -> 1670 | F35: 0.48 | G35: =IF(TableJumiaProducts[[#This Row],[Discount]]<20%, "Low Discount", IF(TableJumiaProducts[[#This Row],[Discount]]<=40%, "Medium Discount", "High Discount")) -> High Discount | H35: 9 | I35: 4.3 | J35: =IF(TableJumiaProducts[[#This Row],[Rating]]="","Uknown", IF(TableJumiaProducts[[#This Row],[Rating]]<3, "Poor", IF(TableJumiaProducts[[#This Row],[Rating]]<4.5, "Average", "Excellent"))) -> Average
A36: Portable Wine Table With Folding Round Table | B36: Home & Office | C36: 1300 | D36: 2500 | E36: =D36-C36 -> 1200 | F36: 0.48 | G36: =IF(TableJumiaProducts[[#This Row],[Discount]]<20%, "Low Discount", IF(TableJumiaProducts[[#This Row],[Discount]]<=40%, "Medium Discount", "High Discount")) -> High Discount | J36: =IF(TableJumiaProducts[[#This Row],[Rating]]="","Uknown", IF(TableJumiaProducts[[#This Row],[Rating]]<3, "Poor", IF(TableJumiaProducts[[#This Row],[Rating]]<4.5, "Average", "Excellent"))) -> Uknown
A37: Christmas Fence Garden Decorations Outdoor For Holiday Home | B37: Garden & Outdoors | C37: 699 | D37: 1343 | E37: =D37-C37 -> 644 | F37: 0.48 | G37: =IF(TableJumiaProducts[[#This Row],[Discount]]<20%, "Low Discount", IF(TableJumiaProducts[[#This Row],[Discount]]<=40%, "Medium Discount", "High Discount")) -> High Discount | J37: =IF(TableJumiaProducts[[#This Row],[Rating]]="","Uknown", IF(TableJumiaProducts[[#This Row],[Rating]]<3, "Poor", IF(TableJumiaProducts[[#This Row],[Rating]]<4.5, "Average", "Excellent"))) -> Uknown
A38: Sewing Machine Needle Threader Stitch Insertion Tool Automatic Quick Sewing | B38: Appliances | C38: 105 | D38: 200 | E38: =D38-C38 -> 95 | F38: 0.48 | G38: =IF(TableJumiaProducts[[#This Row],[Discount]]<20%, "Low Discount", IF(TableJumiaProducts[[#This Row],[Discount]]<=40%, "Medium Discount", "High Discount")) -> High Discount | J38: =IF(TableJumiaProducts[[#This Row],[Rating]]="","Uknown", IF(TableJumiaProducts[[#This Row],[Rating]]<3, "Poor", IF(TableJumiaProducts[[#This Row],[Rating]]<4.5, "Average", "Excellent"))) -> Uknown
A39: Electric LED UV Mosquito Killer Lamp, Outdoor/Indoor Fly Killer Trap Light -USB | B39: Appliances | C39: 1570 | D39: 2988 | E39: =D39-C39 -> 1418 | F39: 0.47 | G39: =IF(TableJumiaProducts[[#This Row],[Discount]]<20%, "Low Discount", IF(TableJumiaProducts[[#This Row],[Discount]]<=40%, "Medium Discount", "High Discount")) -> High Discount | H39: 7 | I39: 2.1 | J39: =IF(TableJumiaProducts[[#This Row],[Rating]]="","Uknown", IF(TableJumiaProducts[[#This Row],[Rating]]<3, "Poor", IF(TableJumiaProducts[[#This Row],[Rating]]<4.5, "Average", "Excellent"))) -> Poor
A40: 7-piece Set Of Storage Bags, Travel Storage Bags, Shoe Bags | B40: Clothing | C40: 968 | D40: 1814 | E40: =D40-C40 -> 846 | F40: 0.47 | G40: =IF(TableJumiaProducts[[#This Row],[Discount]]<20%, "Low Discount", IF(TableJumiaProducts[[#This Row],[Discount]]<=40%, "Medium Discount", "High Discount")) -> High Discount | H40: 6 | I40: 2.2 | J40: =IF(TableJumiaProducts[[#This Row],[Rating]]="","Uknown", IF(TableJumiaProducts[[#This Row],[Rating]]<3, "Poor", IF(TableJumiaProducts[[#This Row],[Rating]]<4.5, "Average", "Excellent"))) -> Poor
...

Sheet Dashboard

Sheet Descriptive Statistics
A1: Overview - Average Metrics | B1: Column1 | F1: Average Discount and Rating Per Product Category
A2: Average Current Price | B2: =AVERAGE(TableJumiaProducts[Current Price]) -> 1186.8929 | F2: Row Labels | G2: Average of Discount | H2: Average of Rating
A3: Avarage Old Price | B3: =AVERAGE(TableJumiaProducts[Old Price]) -> 1811.1071 | F3: Appliances | G3: 0.3603125 | H3: 3.73
A4: Average Discount % | B4: =AVERAGE(TableJumiaProducts[Discount]) -> 0.36776786 | F4: Baby Products | G4: 0.255
A5: Average Rating | B5: =AVERAGE(TableJumiaProducts[Rating]) -> 3.8894737 | F5: Beddings & Sanitary | G5: 0.37666667 | H5: 3.3
F6: Clothing | G6: 0.32111111 | H6: 3.88
A7: Column1 | B7: Product | C7: Category | D7: Current Price | F7: Garden & Outdoors | G7: 0.435 | H7: 3
A8: Most Expensive Product | B8: 32PCS Portable Cordless Drill Set With Cyclic Battery Drive -26 Variable Speed | C8: Appliances | D8: 3750 | F8: Health & Beauty | G8: 0.28 | H8: 4.3
A9: Least Expensive product | B9: 3PCS Single Head Knitting Crochet Sweater Needle Set | C9: Clothing | D9: 38 | F9: Home & Office | G9: 0.40483871 | H9: 4.375
F10: Kitchen & Dining | G10: 0.33052632 | H10: 3.825
F11: Grand Total | G11: 0.36776786 | H11: 3.8894737

Sheet Trend Analysis
A1: Pivot Table for Top and Botton Rated products
A3: Row Labels | B3: Sum of Rating
A4: 1/2/3 Seater Elastic Sofa Cover,Living Room/Home Decor Chair Cover-Grey | B4: 4.5
A5: 100 Pcs Crochet Hook Tool Set Knitting Hook Set With Box | B5: 4.7
A6: 115 Piece Set Of Multifunctional Precision Screwdrivers | B6: 4.5
A7: 12 Litre Black Insulated Lunch Box | B7: 3.8
A8: 12 Litre Insulated Lunch Box Grey | B8: 4.7
A9: 120W Cordless Vacuum Cleaners Handheld Electric Vacuum Cleaner | B9: 2.8
A10: 12V 19500rpm Handheld Electric Angle Grinder Tool - UK - Yellow/Black
A11: 13 In 1 Home Repair Tools Box Kit Set | B11: 3.8
A12: 137 Pieces Cake Decorating Tool Set Baking Supplies | B12: 4.6
A13: 1PC Refrigerator Food Seal Pocket Fridge Bags
A14: 2 Pairs Cowhide Split Leather Work Gloves.32â„‰ Or Above Welding Gloves
A15: 220V 60W Electric Soldering Iron Kits With Tools, Tips, And Multimeter | B15: 4
A16: 24 Grid Wall-mounted Sundries Organiser Fabric Closet Bag Storage Rack
A17: 2PCS Ice Silk Square Cushion Cover Pillowcases - 65x65cm
A18: 2pcs Solar Street Light Flood Light Outdoor
A19: 2PCS/LOT Solar LED Outdoor Intelligent Light Controlled Wall Lamp
A20: 32PCS Portable Cordless Drill Set With Cyclic Battery Drive -26 Variable Speed | B20: 3
A21: 380ML USB Rechargeable Portable Small Blenders And Juicers | B21: 2.3
A22: 3D Waterproof EVA Plastic Shower Curtain 1.8*2Mtrs | B22: 4.6
A23: 3PCS Rotary Scraper Thermomix For Kitchen
A24: 3PCS Single Head Knitting Crochet Sweater Needle Set | B24: 3.3
A25: 4 Piece Coloured Stainless Steel Kitchenware Set
A26: 40cm Gold DIY Acrylic Wall Sticker Clock | B26: 4.8
A27: 4M Float Switch Water Level Controller -Water Tank
A28: 4pcs Bathroom/Kitchen Towel Rack,Roll Paper Holder,Towel Bars,Hook
A29: 5 Pieces/set Of Stainless Steel Induction Cooker Pots | B29: 2.5
A30: 52 Pieces Cake Decorating Tool Set Gift Kit Baking Supplies | B30: 4.1
A31: 53 Pieces/Set Yarn Knitting Crochet Hooks With Bag - Pansies | B31: 4.5
A32: 53Pcs/Set Yarn Knitting Crochet Hooks With Bag - Fortune Cat | B32: 4.7
A33: 5m Waterproof Spherical LED String Lights Outdoor Ball Chain Lights Party Lighting Decoration Adjustable
A34: 5-PCS Stainless Steel Cooking Pot Set With Steamed Slices | B34: 2.1
A35: 6 In 1 Bottle Can Opener Multifunctional Easy Opener
A36: 6 Layers Steel Pipe Assembling Dustproof Storage Shoe Cabinet
A37: 60W Hot Melt Glue Sprayer - Efficient And Stable Glue Dispensing
A38: 7PCS Silicone Thumb Knife Finger Protector Vegetable Harvesting Knife
A39: 7-piece Set Of Storage Bags, Travel Storage Bags, Shoe Bags | B39: 2.2
A40: 8in1 Screwdriver With LED Light
A41: 9pcs Gas Mask, For Painting, Dust, Formaldehyde Grinding, Polishing
...

Sheet Perfomance based on Discount %
A3: Row Labels | B3: Sum of Reviews | C3: Average of Rating | D3: Count of Products
A4: High Discount | B4: 334 | C4: 3.6133333 | D4: 62
A5: Low Discount | B5: 38 | C5: 3.725 | D5: 18
A6: Medium Discount | B6: 351 | C6: 4.2782609 | D6: 32
A7: Grand Total | B7: 723 | C7: 3.8894737 | D7: 112

Sheet Top 10 Products by Reviews
A3: Row Labels | B3: Sum of Reviews
A4: 100 Pcs Crochet Hook Tool Set Knitting Hook Set With Box | B4: 39
A5: 120W Cordless Vacuum Cleaners Handheld Electric Vacuum Cleaner | B5: 69
A6: 137 Pieces Cake Decorating Tool Set Baking Supplies | B6: 55
A7: 3D Waterproof EVA Plastic Shower Curtain 1.8*2Mtrs | B7: 44
A8: 52 Pieces Cake Decorating Tool Set Gift Kit Baking Supplies | B8: 20
A9: 53 Pieces/Set Yarn Knitting Crochet Hooks With Bag - Pansies | B9: 32
A10: 53Pcs/Set Yarn Knitting Crochet Hooks With Bag - Fortune Cat | B10: 20
A11: Electronic Digital Display Vernier Caliper | B11: 49
A12: Portable Mini Cordless Car Vacuum Cleaner - Blue | B12: 24
A13: Punch-free Great Load Bearing Bathroom Storage Rack Wall Shelf-White | B13: 36
A14: Grand Total | B14: 388

Sheet Products by Discount Category
A3: Row Labels | B3: Count of Products
A4: High Discount | B4: 62
A5: Low Discount | B5: 18
A6: Medium Discount | B6: 32
A7: Grand Total | B7: 112

Sheet Products by Rating Category
A3: Row Labels | B3: Count of Products
A4: Average | B4: 22
A5: Excellent | B5: 23
A6: Poor | B6: 12
A7: Uknown | B7: 55
A8: Grand Total | B8: 112

Sheet PT for Perfomance Comparison 

Sheet PT for Top & Bottom 10 Products
A3: Row Labels | B3: Average of Discount
A4: 3PCS Single Head Knitting Crochet Sweater Needle Set | B4: 0.53
A5: 5-PCS Stainless Steel Cooking Pot Set With Steamed Slices | B5: 0.55
A6: 6 In 1 Bottle Can Opener Multifunctional Easy Opener | B6: 0.64
A7: Classic Black Cat Cotton Hemp Pillow Case For Home Car | B7: 0.53
A8: Creative Owl Shape Keychain Black | B8: 0.55
A9: Exfoliate And Exfoliate Face Towel - Black | B9: 0.52
A10: Intelligent LED Body Sensor Wireless Lighting Night Light USB | B10: 0.52
A11: LASA 3 Tier Bamboo Shoe Bench Storage Shelf | B11: 0.54
A12: LASA Folding Table Serving Stand | B12: 0.55
A13: Mythco 120COB Solar Wall Ligt With Motion Sensor And Remote Control 3 Modes | B13: 0.54
A14: Grand Total | B14: 0.54727273
